Workbook

Sheet Monthly
A2: Retail Ledger monthly analysis
A3: All recorded months in totals; December 2011 is partial and excluded from the trend chart.
A5: Metric | B5: GBP
A6: Gross sales | B6: =SUM(B11:B23) -> 10642111
A7: Cancellation value | B7: =SUM(C11:C23) -> 893979.73
A8: Net transaction value | B8: =SUM(D11:D23) -> 9748131.1
A10: Month | B10: Gross GBP | C10: Cancelled GBP | D10: Net GBP | E10: Cancel / gross | F10: Sales invoices | G10: Identified buyers | H10: Coverage
A11: 2010-12 | B11: 821452.73 | C11: 74729.12 | D11: =B11-C11 -> 746723.61 | E11: =IF(B11=0,"n.a.",C11/B11) -> 0.090971905 | F11: 1559 | G11: 885 | H11: Full
A12: 2011-01 | B12: 689811.61 | C12: 131363.05 | D12: =B12-C12 -> 558448.56 | E12: =IF(B12=0,"n.a.",C12/B12) -> 0.19043323 | F12: 1086 | G12: 741 | H12: Full
A13: 2011-02 | B13: 522545.56 | C13: 25519.15 | D13: =B13-C13 -> 497026.41 | E13: =IF(B13=0,"n.a.",C13/B13) -> 0.04883622 | F13: 1100 | G13: 758 | H13: Full
A14: 2011-03 | B14: 716215.26 | C14: 34201.28 | D14: =B14-C14 -> 682013.98 | E14: =IF(B14=0,"n.a.",C14/B14) -> 0.047752794 | F14: 1454 | G14: 974 | H14: Full
A15: 2011-04 | B15: 536968.49 | C15: 44600.65 | D15: =B15-C15 -> 492367.84 | E15: =IF(B15=0,"n.a.",C15/B15) -> 0.083060088 | F15: 1246 | G15: 856 | H15: Full
A16: 2011-05 | B16: 769296.61 | C16: 47202.51 | D16: =B16-C16 -> 722094.1 | E16: =IF(B16=0,"n.a.",C16/B16) -> 0.061358011 | F16: 1681 | G16: 1056 | H16: Full
A17: 2011-06 | B17: 760547.01 | C17: 70569.78 | D17: =B17-C17 -> 689977.23 | E17: =IF(B17=0,"n.a.",C17/B17) -> 0.092788189 | F17: 1533 | G17: 991 | H17: Full
A18: 2011-07 | B18: 718076.12 | C18: 37919.13 | D18: =B18-C18 -> 680156.99 | E18: =IF(B18=0,"n.a.",C18/B18) -> 0.05280656 | F18: 1475 | G18: 949 | H18: Full
A19: 2011-08 | B19: 757841.38 | C19: 54330.8 | D19: =B19-C19 -> 703510.58 | E19: =IF(B19=0,"n.a.",C19/B19) -> 0.071691519 | F19: 1361 | G19: 935 | H19: Full
A20: 2011-09 | B20: 1056435.2 | C20: 38838.51 | D20: =B20-C20 -> 1017596.7 | E20: =IF(B20=0,"n.a.",C20/B20) -> 0.036763741 | F20: 1837 | G20: 1266 | H20: Full
A21: 2011-10 | B21: 1151263.7 | C21: 81895.5 | D21: =B21-C21 -> 1069368.2 | E21: =IF(B21=0,"n.a.",C21/B21) -> 0.071135308 | F21: 2040 | G21: 1364 | H21: Full
A22: 2011-11 | B22: 1503866.8 | C22: 47720.98 | D22: =B22-C22 -> 1456145.8 | E22: =IF(B22=0,"n.a.",C22/B22) -> 0.031732186 | F22: 2769 | G22: 1664 | H22: Full
A23: 2011-12 | B23: 637790.33 | C23: 205089.27 | D23: =B23-C23 -> 432701.06 | E23: =IF(B23=0,"n.a.",C23/B23) -> 0.32156221 | F23: 819 | G23: 615 | H23: Through Dec 9
A25: Cancellation value is a value ratio, not a product-return rate. Records are not matched to original sales.
A27: Transaction value is not profit or settled cash; the source does not contain those measures.

Sheet Markets
A2: Markets and cancellation value
A3: Full source period, including partial December 2011; sorted by net transaction value.
A6: Country | B6: Gross GBP | C6: Cancelled GBP | D6: Net GBP | E6: Sales invoices | F6: Net share | G6: Cancel / gross
A7: United Kingdom | B7: 9001744.1 | C7: 812491.79 | D7: =B7-C7 -> 8189252.3 | E7: 18019 | F7: =D7/SUM($D$7:$D$44) -> 0.84008434 | G7: =IF(B7=0,"n.a.",C7/B7) -> 0.090259374
A8: Netherlands | B8: 285446.34 | C8: 784.8 | D8: =B8-C8 -> 284661.54 | E8: 94 | F8: =D8/SUM($D$7:$D$44) -> 0.029201653 | G8: =IF(B8=0,"n.a.",C8/B8) -> 0.0027493784
A9: EIRE | B9: 283140.52 | C9: 20147.14 | D9: =B9-C9 -> 262993.38 | E9: 288 | F9: =D9/SUM($D$7:$D$44) -> 0.026978851 | G9: =IF(B9=0,"n.a.",C9/B9) -> 0.071155976
A10: Germany | B10: 228678.4 | C10: 7168.93 | D10: =B10-C10 -> 221509.47 | E10: 457 | F10: =D10/SUM($D$7:$D$44) -> 0.022723276 | G10: =IF(B10=0,"n.a.",C10/B10) -> 0.031349397
A11: France | B11: 209625.37 | C11: 12308.26 | D11: =B11-C11 -> 197317.11 | E11: 392 | F11: =D11/SUM($D$7:$D$44) -> 0.020241532 | G11: =IF(B11=0,"n.a.",C11/B11) -> 0.058715508
A12: Australia | B12: 138453.81 | C12: 1444.04 | D12: =B12-C12 -> 137009.77 | E12: 57 | F12: =D12/SUM($D$7:$D$44) -> 0.014054978 | G12: =IF(B12=0,"n.a.",C12/B12) -> 0.01042976
A13: Switzerland | B13: 57067.6 | C13: 704.55 | D13: =B13-C13 -> 56363.05 | E13: 54 | F13: =D13/SUM($D$7:$D$44) -> 0.0057819339 | G13: =IF(B13=0,"n.a.",C13/B13) -> 0.012345885
A14: Spain | B14: 61558.56 | C14: 6802.53 | D14: =B14-C14 -> 54756.03 | E14: 90 | F14: =D14/SUM($D$7:$D$44) -> 0.0056170798 | G14: =IF(B14=0,"n.a.",C14/B14) -> 0.11050502
A15: Belgium | B15: 41196.34 | C15: 285.38 | D15: =B15-C15 -> 40910.96 | E15: 98 | F15: =D15/SUM($D$7:$D$44) -> 0.0041968004 | G15: =IF(B15=0,"n.a.",C15/B15) -> 0.0069273144
A16: Sweden | B16: 38367.83 | C16: 1782.42 | D16: =B16-C16 -> 36585.41 | E16: 36 | F16: =D16/SUM($D$7:$D$44) -> 0.0037530691 | G16: =IF(B16=0,"n.a.",C16/B16) -> 0.046456107
A17: Japan | B17: 37416.37 | C17: 2075.75 | D17: =B17-C17 -> 35340.62 | E17: 19 | F17: =D17/SUM($D$7:$D$44) -> 0.0036253739 | G17: =IF(B17=0,"n.a.",C17/B17) -> 0.055477055
A18: Norway | B18: 36165.44 | C18: 1001.98 | D18: =B18-C18 -> 35163.46 | E18: 36 | F18: =D18/SUM($D$7:$D$44) -> 0.0036072002 | G18: =IF(B18=0,"n.a.",C18/B18) -> 0.027705456
... A44: Saudi Arabia | B44: 145.92 | C44: 14.75 | D44: =B44-C44 -> 131.17 | E44: 1 | F44: =D44/SUM($D$7:$D$44) -> 1.3455913e-05 | G44: =IF(B44=0,"n.a.",C44/B44) -> 0.10108279

Sheet Cohorts
A2: Observed customer retention
A3: First observed purchase cohort; identified buyers only; December 2011 excluded.
A4: Blank = period not observed. Zero = observed month with no repeat purchasers.
A6: Cohort | B6: Month 0 | C6: Month 1 | D6: Month 2 | E6: Month 3 | F6: Month 4 | G6: Month 5 | H6: Month 6 | I6: Month 7 | J6: Month 8 | K6: Month 9 | L6: Month 10 | M6: Month 11 | N6: Cohort size
A7: =A25 -> 2010-12 | B7: =B25/$N25 -> 1 | C7: =C25/$N25 -> 0.36610169 | D7: =D25/$N25 -> 0.32316384 | E7: =E25/$N25 -> 0.38418079 | F7: =F25/$N25 -> 0.36271186 | G7: =G25/$N25 -> 0.39774011 | H7: =H25/$N25 -> 0.36271186 | I7: =I25/$N25 -> 0.34915254 | ... M7: =M25/$N25 -> 0.50282486 | N7: =N25 -> 885
A8: =A26 -> 2011-01 | B8: =B26/$N26 -> 1 | C8: =C26/$N26 -> 0.2206235 | D8: =D26/$N26 -> 0.26618705 | E8: =E26/$N26 -> 0.23021583 | F8: =F26/$N26 -> 0.32134293 | G8: =G26/$N26 -> 0.28776978 | H8: =H26/$N26 -> 0.2470024 | I8: =I26/$N26 -> 0.24220624 | ... L8: =L26/$N26 -> 0.36450839 | N8: =N26 -> 417
A9: =A27 -> 2011-02 | B9: =B27/$N27 -> 1 | C9: =C27/$N27 -> 0.18684211 | D9: =D27/$N27 -> 0.18684211 | E9: =E27/$N27 -> 0.28421053 | F9: =F27/$N27 -> 0.27105263 | G9: =G27/$N27 -> 0.24736842 | H9: =H27/$N27 -> 0.25263158 | I9: =I27/$N27 -> 0.27894737 | ... K9: =K27/$N27 -> 0.30526316 | N9: =N27 -> 380
A10: =A28 -> 2011-03 | B10: =B28/$N28 -> 1 | C10: =C28/$N28 -> 0.15044248 | D10: =D28/$N28 -> 0.25221239 | E10: =E28/$N28 -> 0.19911504 | F10: =F28/$N28 -> 0.22345133 | G10: =G28/$N28 -> 0.16814159 | H10: =H28/$N28 -> 0.26769912 | I10: =I28/$N28 -> 0.2300885 | J10: =J28/$N28 -> 0.27876106 | N10: =N28 -> 452
A11: =A29 -> 2011-04 | B11: =B29/$N29 -> 1 | C11: =C29/$N29 -> 0.21333333 | D11: =D29/$N29 -> 0.20333333 | E11: =E29/$N29 -> 0.21 | F11: =F29/$N29 -> 0.19666667 | G11: =G29/$N29 -> 0.22666667 | H11: =H29/$N29 -> 0.21666667 | I11: =I29/$N29 -> 0.26 | N11: =N29 -> 300
A12: =A30 -> 2011-05 | B12: =B30/$N30 -> 1 | C12: =C30/$N30 -> 0.19014085 | D12: =D30/$N30 -> 0.17253521 | E12: =E30/$N30 -> 0.17253521 | F12: =F30/$N30 -> 0.20774648 | G12: =G30/$N30 -> 0.23239437 | H12: =H30/$N30 -> 0.26408451 | N12: =N30 -> 284
A13: =A31 -> 2011-06 | B13: =B31/$N31 -> 1 | C13: =C31/$N31 -> 0.17355372 | D13: =D31/$N31 -> 0.15702479 | E13: =E31/$N31 -> 0.26446281 | F13: =F31/$N31 -> 0.23140496 | G13: =G31/$N31 -> 0.33471074 | N13: =N31 -> 242
A14: =A32 -> 2011-07 | B14: =B32/$N32 -> 1 | C14: =C32/$N32 -> 0.18085106 | D14: =D32/$N32 -> 0.20744681 | E14: =E32/$N32 -> 0.22340426 | F14: =F32/$N32 -> 0.2712766 | N14: =N32 -> 188
A15: =A33 -> 2011-08 | B15: =B33/$N33 -> 1 | C15: =C33/$N33 -> 0.20710059 | D15: =D33/$N33 -> 0.24852071 | E15: =E33/$N33 -> 0.24260355 | N15: =N33 -> 169
A16: =A34 -> 2011-09 | B16: =B34/$N34 -> 1 | C16: =C34/$N34 -> 0.23411371 | D16: =D34/$N34 -> 0.30100334 | N16: =N34 -> 299
A17: =A35 -> 2011-10 | B17: =B35/$N35 -> 1 | C17: =C35/$N35 -> 0.24022346 | N17: =N35 -> 358
A18: =A36 -> 2011-11 | B18: =B36/$N36 -> 1 | N18: =N36 -> 323
A24: Source counts | B24: Month 0 | C24: Month 1 | D24: Month 2 | E24: Month 3 | F24: Month 4 | G24: Month 5 | H24: Month 6 | I24: Month 7 | J24: Month 8 | K24: Month 9 | L24: Month 10 | M24: Month 11 | N24: Cohort size
A25: 2010-12 | B25: 885 | C25: 324 | D25: 286 | E25: 340 | F25: 321 | G25: 352 | H25: 321 | I25: 309 | J25: 313 | K25: 350 | L25: 331 | M25: 445 | N25: 885
A26: 2011-01 | B26: 417 | C26: 92 | D26: 111 | E26: 96 | F26: 134 | G26: 120 | H26: 103 | I26: 101 | J26: 125 | K26: 136 | L26: 152 | N26: 417
A27: 2011-02 | B27: 380 | C27: 71 | D27: 71 | E27: 108 | F27: 103 | G27: 94 | H27: 96 | I27: 106 | J27: 94 | K27: 116 | N27: 380
A28: 2011-03 | B28: 452 | C28: 68 | D28: 114 | E28: 90 | F28: 101 | G28: 76 | H28: 121 | I28: 104 | J28: 126 | N28: 452
A29: 2011-04 | B29: 300 | C29: 64 | D29: 61 | E29: 63 | F29: 59 | G29: 68 | H29: 65 | I29: 78 | N29: 300
A30: 2011-05 | B30: 284 | C30: 54 | D30: 49 | E30: 49 | F30: 59 | G30: 66 | H30: 75 | N30: 284
A31: 2011-06 | B31: 242 | C31: 42 | D31: 38 | E31: 64 | F31: 56 | G31: 81 | N31: 242
A32: 2011-07 | B32: 188 | C32: 34 | D32: 39 | E32: 42 | F32: 51 | N32: 188
A33: 2011-08 | B33: 169 | C33: 35 | D33: 42 | E33: 41 | N33: 169
A34: 2011-09 | B34: 299 | C34: 70 | D34: 90 | N34: 299
A35: 2011-10 | B35: 358 | C35: 86 | N35: 358
A36: 2011-11 | B36: 323 | N36: 323

Sheet Audit
A2: Source reconciliation and data quality
A3: Source: Chen (2015), UCI Online Retail, CC BY 4.0. https://doi.org/10.24432/C5BW33
A5: Classification | B5: Source rows | C5: Signed GBP
A6: cancellation | B6: 9251 | C6: -893979.73
A7: duplicate | B7: 5268 | C7: 21740.98
A8: nonpositive_price | B8: 2512 | C8: -22124.12
A9: sale | B9: 524878 | C9: 10642111
A12: Classified total | B12: =SUM(B6:B10) -> 541909 | C12: =SUM(C6:C10) -> 9747747.9
A13: Raw source total | B13: 541909 | C13: 9747747.9
A14: Reconciliation difference | B14: =B12-B13 -> 0 | C14: =C12-C13 -> 0
A17: Missing customer ID rows | B17: 135080
A18: Missing description rows | B18: 1454
A19: Exact duplicate rows | B19: 5268
A21: Exact duplicate removal is an assumption, not proof of erroneous transactions. Raw records are retained.
A23: Nonpositive prices and other adjustments remain in this audit but are excluded from sales measures.

Sheet Explore
A2: Country and period analysis
A3: Change the amber cells. Month keys use YYYYMM. December 2011 is partial.
A5: Country | B5: Germany | J5: Countries | K5: Month keys
A6: Start month | B6: 201101 | J6: United Kingdom | K6: 201012
A7: End month | B7: 201106 | J7: Netherlands | K7: 201101
J8: EIRE | K8: 201102
A9: Selection check | B9: =IF(AND(COUNTIF(J6:J43,B5)=1,COUNTIF(K6:K18,B6)=1,COUNTIF(K6:K18,B7)=1,B6<=B7),"Valid","Check selection") -> Valid | J9: Germany | K9: 201103
J10: France | K10: 201104
A11: Selected-period metric | B11: Result | J11: Australia | K11: 201105
A12: Gross sales | B12: =IF(B9<>"Valid","Check selection",SUMIFS(CountryMonth!$D$6:$D$319,CountryMonth!$C$6:$C$319,$B$5,CountryMonth!$B$6:$B$319,">="&$B$6,CountryMonth!$B$6:$B$319,"<="&$B$7)) -> 92151.17 | J12: Switzerland | K12: 201106
A13: Cancellation value | B13: =IF(B9<>"Valid","Check selection",SUMIFS(CountryMonth!$E$6:$E$319,CountryMonth!$C$6:$C$319,$B$5,CountryMonth!$B$6:$B$319,">="&$B$6,CountryMonth!$B$6:$B$319,"<="&$B$7)) -> 2018.99 | J13: Spain | K13: 201107
A14: Net transaction value | B14: =IF(B9<>"Valid","Check selection",B12-B13) -> 90132.18 | J14: Belgium | K14: 201108
A15: Cancellation / gross | B15: =IF(B9<>"Valid","Check selection",IF(B12=0,"n.a.",B13/B12)) -> 0.021909543 | J15: Sweden | K15: 201109
A16: Sales invoices | B16: =IF(B9<>"Valid","Check selection",SUMIFS(CountryMonth!$G$6:$G$319,CountryMonth!$C$6:$C$319,$B$5,CountryMonth!$B$6:$B$319,">="&$B$6,CountryMonth!$B$6:$B$319,"<="&$B$7)) -> 171 | J16: Japan | K16: 201110
A17: Observed country-months | B17: =IF(B9<>"Valid","Check selection",COUNTIFS(CountryMonth!$C$6:$C$319,$B$5,CountryMonth!$B$6:$B$319,">="&$B$6,CountryMonth!$B$6:$B$319,"<="&$B$7)) -> 6 | J17: Norway | K17: 201111
J18: Portugal | K18: 201112
J19: Finland
A20: Full-source-period comparison | B20: Result | J20: Channel Islands
A21: Country net value | B21: =XLOOKUP(B5,Markets!A7:A44,Markets!D7:D44,"Country not found",0) -> 221509.47 | J21: Denmark
A22: Selected / full-period net | B22: =IF(B9<>"Valid","Check selection",IF(B21=0,"n.a.",B14/B21)) -> 0.40689989 | J22: Italy
J23: Cyprus
J24: Austria
A25: SUMIFS totals the selected country and months; COUNTIFS counts observed month rows, not customers. | J25: Hong Kong
J26: Singapore
A27: XLOOKUP retrieves the selected country’s full-period net value from Markets. | J27: Israel
J28: Poland
A29: No matching source rows gives zero value and zero observed months. Invalid selections are flagged. | J29: Unspecified
J30: Greece
A31: Country Pivot contains a native Excel PivotTable with cached totals. Refresh after source changes. | J31: Iceland
J32: Canada
A33: Power Query setup is provided separately; this workbook does not yet have an active query connection. | J33: Malta
J34: United Arab Emirates
J35: USA
J36: Lebanon
J37: Lithuania
J38: European Community
J39: Brazil
J40: RSA
J41: Czech Republic
J42: Bahrain
...

Sheet CountryMonth
A2: Country-month source aggregates
A3: UCI Online Retail, Chen (2015), CC BY 4.0; SQL export: exports/country_month.csv.
A5: Month | B5: MonthKey | C5: Country | D5: GrossGBP | E5: CancelledGBP | F5: NetGBP | G5: SalesInvoices
A6: 2010-12 | B6: 201012 | C6: Australia | D6: 965.35 | E6: 27.75 | F6: 937.6 | G6: 3
A7: 2010-12 | B7: 201012 | C7: Austria | D7: 277.2 | E7: 20.16 | F7: 257.04 | G7: 1
A8: 2010-12 | B8: 201012 | C8: Bahrain | D8: 205.74 | E8: 0 | F8: 205.74 | G8: 1
A9: 2010-12 | B9: 201012 | C9: Belgium | D9: 1809.91 | E9: 0 | F9: 1809.91 | G9: 5
A10: 2010-12 | B10: 201012 | C10: Channel Islands | D10: 363.53 | E10: 0 | F10: 363.53 | G10: 1
A11: 2010-12 | B11: 201012 | C11: Cyprus | D11: 1587.07 | E11: 0 | F11: 1587.07 | G11: 1
A12: 2010-12 | B12: 201012 | C12: Denmark | D12: 1281.5 | E12: 0 | F12: 1281.5 | G12: 1
A13: 2010-12 | B13: 201012 | C13: EIRE | D13: 10033.26 | E13: 1003.31 | F13: 9029.95 | G13: 17
A14: 2010-12 | B14: 201012 | C14: Finland | D14: 892.8 | E14: 0 | F14: 892.8 | G14: 1
A15: 2010-12 | B15: 201012 | C15: France | D15: 9616.31 | E15: 40.95 | F15: 9575.36 | G15: 21
A16: 2010-12 | B16: 201012 | C16: Germany | D16: 15205.74 | E16: 678.3 | F16: 14527.44 | G16: 30
A17: 2010-12 | B17: 201012 | C17: Iceland | D17: 711.79 | E17: 0 | F17: 711.79 | G17: 1
... A319: 2011-12 | B319: 201112 | C319: United Kingdom | D319: 591619.74 | E319: 203851.26 | F319: 387768.48 | G319: 746

Sheet Country Pivot
A2: Country PivotTable
A3: Full source period; includes partial December 2011. Source: CountryMonthData.
A6: Country | B6: Sum of GrossGBP | C6: Sum of CancelledGBP | D6: Sum of NetGBP
A7: Australia | B7: 138453.81 | C7: 1444.04 | D7: 137009.77
A8: Austria | B8: 10198.68 | C8: 44.36 | D8: 10154.32
A9: Bahrain | B9: 754.14 | C9: 205.74 | D9: 548.4
A10: Belgium | B10: 41196.34 | C10: 285.38 | D10: 40910.96
A11: Brazil | B11: 1143.6 | C11: 0 | D11: 1143.6
A12: Canada | B12: 3666.38 | C12: 0 | D12: 3666.38
A13: Channel Islands | B13: 20440.54 | C13: 364.15 | D13: 20076.39
A14: Cyprus | B14: 13502.85 | C14: 644.09 | D14: 12858.76
A15: Czech Republic | B15: 826.74 | C15: 119.02 | D15: 707.72
A16: Denmark | B16: 18955.34 | C16: 187.2 | D16: 18768.14
A17: EIRE | B17: 283140.52 | C17: 20147.14 | D17: 262993.38
A18: European Community | B18: 1300.25 | C18: 8.5 | D18: 1291.75
... A45: Grand Total | B45: 10642111 | C45: 893979.73 | D45: 9748131.1
